Workbook

Sheet Panel de Cumplimiento
A1: PANEL DE CUMPLIMIENTO DE MANTENCIÓN | I1: PANEL DE CUMPLIMIENTO RECAMBIO/ INFORME / PRESUPUESTO
A3: Edificio / Ubicación | B3: Categoría | C3: Prioridad | D3: Total Tareas | E3: Tareas Al Día | F3: % Cumplimiento | G3: Estatus | I3: Edificio / Ubicación | J3: Total Tareas | K3: Activo | L3: Cambiar | M3: Cambiar o Inspección externa | N3: Presupuestar
A4: EDIFICIO PRINCIPAL | B4: SEGURIDAD | C4: 1 | D4: =COUNTIFS('Maestro infraestructura'!$A$2:$A$1052, A4,'Maestro infraestructura'!$X$2:$X$1052,B4,'Maestro infraestructura'!$Y$2:$Y$1052,C4) -> 54 | E4: =COUNTIFS('Maestro infraestructura'!$A$2:$A$1051, A4,'Maestro infraestructura'!$X$2:$X$1051,B4,'Maestro infraestructura'!$Y$2:$Y$1051,C4,'Maestro infraestructura'!$V$2:$V$1051, "AL DÍA") -> 54 | F4: =IF(D4=0,100%,IF(D4>0,E4/D4,0)) -> 1 | G4: =IF(F4=1, "✅ ÓPTIMO", IF(F4>=0.8, "⚠️ PRECAUCIÓN", "❌ CRÍTICO")) -> ✅ ÓPTIMO | I4: EDIFICIO PRINCIPAL | J4: =COUNTIFS('Maestro infraestructura'!$A$2:$A$1052, I4) -> 618 | K4: =+COUNTIFS('Maestro infraestructura'!$A$2:$A$1051, I4,'Maestro infraestructura'!$K$2:$K$1051, $K$3) -> 572 | L4: =+COUNTIFS('Maestro infraestructura'!$A$2:$A$1051, I4,'Maestro infraestructura'!$K$2:$K$1051, $L$3) -> 0 | M4: =+COUNTIFS('Maestro infraestructura'!$A$2:$A$1051, I4,'Maestro infraestructura'!$K$2:$K$1051, $M$3) -> 44 | N4: =+COUNTIFS('Maestro infraestructura'!$A$2:$A$1051, I4,'Maestro infraestructura'!$K$2:$K$1051, $N$3) -> 2
A5: EDIFICIO PRINCIPAL | B5: SEGURIDAD | C5: 2 | D5: =COUNTIFS('Maestro infraestructura'!$A$2:$A$1052, A5,'Maestro infraestructura'!$X$2:$X$1052,B5,'Maestro infraestructura'!$Y$2:$Y$1052,C5) -> 1 | E5: =COUNTIFS('Maestro infraestructura'!$A$2:$A$1051, A5,'Maestro infraestructura'!$X$2:$X$1051,B5,'Maestro infraestructura'!$Y$2:$Y$1051,C5,'Maestro infraestructura'!$V$2:$V$1051, "AL DÍA") -> 1 | F5: =IF(D5=0,100%,IF(D5>0,E5/D5,0)) -> 1 | G5: =IF(F5=1, "✅ ÓPTIMO", IF(F5>=0.8, "⚠️ PRECAUCIÓN", "❌ CRÍTICO")) -> ✅ ÓPTIMO | I5: CICLO INICIAL | J5: =COUNTIFS('Maestro infraestructura'!$A$2:$A$1052, I5) -> 153 | K5: =+COUNTIFS('Maestro infraestructura'!$A$2:$A$1051, I5,'Maestro infraestructura'!$K$2:$K$1051, $K$3) -> 153 | L5: =+COUNTIFS('Maestro infraestructura'!$A$2:$A$1051, I5,'Maestro infraestructura'!$K$2:$K$1051, $L$3) -> 0 | M5: =+COUNTIFS('Maestro infraestructura'!$A$2:$A$1051, I5,'Maestro infraestructura'!$K$2:$K$1051, $M$3) -> 0 | N5: =+COUNTIFS('Maestro infraestructura'!$A$2:$A$1051, I5,'Maestro infraestructura'!$K$2:$K$1051, $N$3) -> 0
A6: EDIFICIO PRINCIPAL | B6: SEGURIDAD | C6: 3 | D6: =COUNTIFS('Maestro infraestructura'!$A$2:$A$1052, A6,'Maestro infraestructura'!$X$2:$X$1052,B6,'Maestro infraestructura'!$Y$2:$Y$1052,C6) -> 0 | E6: =COUNTIFS('Maestro infraestructura'!$A$2:$A$1051, A6,'Maestro infraestructura'!$X$2:$X$1051,B6,'Maestro infraestructura'!$Y$2:$Y$1051,C6,'Maestro infraestructura'!$V$2:$V$1051, "AL DÍA") -> 0 | F6: =IF(D6=0,100%,IF(D6>0,E6/D6,0)) -> 1 | G6: =IF(F6=1, "✅ ÓPTIMO", IF(F6>=0.8, "⚠️ PRECAUCIÓN", "❌ CRÍTICO")) -> ✅ ÓPTIMO | I6: NEUBAU | J6: =COUNTIFS('Maestro infraestructura'!$A$2:$A$1052, I6) -> 175 | K6: =+COUNTIFS('Maestro infraestructura'!$A$2:$A$1051, I6,'Maestro infraestructura'!$K$2:$K$1051, $K$3) -> 175 | L6: =+COUNTIFS('Maestro infraestructura'!$A$2:$A$1051, I6,'Maestro infraestructura'!$K$2:$K$1051, $L$3) -> 0 | M6: =+COUNTIFS('Maestro infraestructura'!$A$2:$A$1051, I6,'Maestro infraestructura'!$K$2:$K$1051, $M$3) -> 0 | N6: =+COUNTIFS('Maestro infraestructura'!$A$2:$A$1051, I6,'Maestro infraestructura'!$K$2:$K$1051, $N$3) -> 0
A7: EDIFICIO PRINCIPAL | B7: LEGAL | C7: 1 | D7: =COUNTIFS('Maestro infraestructura'!$A$2:$A$1052, A7,'Maestro infraestructura'!$X$2:$X$1052,B7,'Maestro infraestructura'!$Y$2:$Y$1052,C7) -> 4 | E7: =COUNTIFS('Maestro infraestructura'!$A$2:$A$1051, A7,'Maestro infraestructura'!$X$2:$X$1051,B7,'Maestro infraestructura'!$Y$2:$Y$1051,C7,'Maestro infraestructura'!$V$2:$V$1051, "AL DÍA") -> 0 | F7: =IF(D7=0,100%,IF(D7>0,E7/D7,0)) -> 0 | G7: =IF(F7=1, "✅ ÓPTIMO", IF(F7>=0.8, "⚠️ PRECAUCIÓN", "❌ CRÍTICO")) -> ❌ CRÍTICO | I7: SPIELGRUPPE | J7: =COUNTIFS('Maestro infraestructura'!$A$2:$A$1052, I7) -> 47 | K7: =+COUNTIFS('Maestro infraestructura'!$A$2:$A$1051, I7,'Maestro infraestructura'!$K$2:$K$1051, $K$3) -> 45 | L7: =+COUNTIFS('Maestro infraestructura'!$A$2:$A$1051, I7,'Maestro infraestructura'!$K$2:$K$1051, $L$3) -> 0 | M7: =+COUNTIFS('Maestro infraestructura'!$A$2:$A$1051, I7,'Maestro infraestructura'!$K$2:$K$1051, $M$3) -> 1 | N7: =+COUNTIFS('Maestro infraestructura'!$A$2:$A$1051, I7,'Maestro infraestructura'!$K$2:$K$1051, $N$3) -> 0
A8: EDIFICIO PRINCIPAL | B8: LEGAL | C8: 2 | D8: =COUNTIFS('Maestro infraestructura'!$A$2:$A$1052, A8,'Maestro infraestructura'!$X$2:$X$1052,B8,'Maestro infraestructura'!$Y$2:$Y$1052,C8) -> 13 | E8: =COUNTIFS('Maestro infraestructura'!$A$2:$A$1051, A8,'Maestro infraestructura'!$X$2:$X$1051,B8,'Maestro infraestructura'!$Y$2:$Y$1051,C8,'Maestro infraestructura'!$V$2:$V$1051, "AL DÍA") -> 4 | F8: =IF(D8=0,100%,IF(D8>0,E8/D8,0)) -> 0.30769231 | G8: =IF(F8=1, "✅ ÓPTIMO", IF(F8>=0.8, "⚠️ PRECAUCIÓN", "❌ CRÍTICO")) -> ❌ CRÍTICO | I8: CASINO | J8: =COUNTIFS('Maestro infraestructura'!$A$2:$A$1052, I8) -> 14 | K8: =+COUNTIFS('Maestro infraestructura'!$A$2:$A$1051, I8,'Maestro infraestructura'!$K$2:$K$1051, $K$3) -> 13 | L8: =+COUNTIFS('Maestro infraestructura'!$A$2:$A$1051, I8,'Maestro infraestructura'!$K$2:$K$1051, $L$3) -> 0 | M8: =+COUNTIFS('Maestro infraestructura'!$A$2:$A$1051, I8,'Maestro infraestructura'!$K$2:$K$1051, $M$3) -> 1 | N8: =+COUNTIFS('Maestro infraestructura'!$A$2:$A$1051, I8,'Maestro infraestructura'!$K$2:$K$1051, $N$3) -> 0
A9: EDIFICIO PRINCIPAL | B9: LEGAL | C9: 3 | D9: =COUNTIFS('Maestro infraestructura'!$A$2:$A$1052, A9,'Maestro infraestructura'!$X$2:$X$1052,B9,'Maestro infraestructura'!$Y$2:$Y$1052,C9) -> 0 | E9: =COUNTIFS('Maestro infraestructura'!$A$2:$A$1051, A9,'Maestro infraestructura'!$X$2:$X$1051,B9,'Maestro infraestructura'!$Y$2:$Y$1051,C9,'Maestro infraestructura'!$V$2:$V$1051, "AL DÍA") -> 0 | F9: =IF(D9=0,100%,IF(D9>0,E9/D9,0)) -> 1 | G9: =IF(F9=1, "✅ ÓPTIMO", IF(F9>=0.8, "⚠️ PRECAUCIÓN", "❌ CRÍTICO")) -> ✅ ÓPTIMO | I9: PISCINA | J9: =COUNTIFS('Maestro infraestructura'!$A$2:$A$1052, I9) -> 23 | K9: =+COUNTIFS('Maestro infraestructura'!$A$2:$A$1051, I9,'Maestro infraestructura'!$K$2:$K$1051, $K$3) -> 21 | L9: =+COUNTIFS('Maestro infraestructura'!$A$2:$A$1051, I9,'Maestro infraestructura'!$K$2:$K$1051, $L$3) -> 1 | M9: =+COUNTIFS('Maestro infraestructura'!$A$2:$A$1051, I9,'Maestro infraestructura'!$K$2:$K$1051, $M$3) -> 0 | N9: =+COUNTIFS('Maestro infraestructura'!$A$2:$A$1051, I9,'Maestro infraestructura'!$K$2:$K$1051, $N$3) -> 1
A10: EDIFICIO PRINCIPAL | B10: OPERACIÓN | C10: 1 | D10: =COUNTIFS('Maestro infraestructura'!$A$2:$A$1052, A10,'Maestro infraestructura'!$X$2:$X$1052,B10,'Maestro infraestructura'!$Y$2:$Y$1052,C10) -> 1 | E10: =COUNTIFS('Maestro infraestructura'!$A$2:$A$1051, A10,'Maestro infraestructura'!$X$2:$X$1051,B10,'Maestro infraestructura'!$Y$2:$Y$1051,C10,'Maestro infraestructura'!$V$2:$V$1051, "AL DÍA") -> 1 | F10: =IF(D10=0,100%,IF(D10>0,E10/D10,0)) -> 1 | G10: =IF(F10=1, "✅ ÓPTIMO", IF(F10>=0.8, "⚠️ PRECAUCIÓN", "❌ CRÍTICO")) -> ✅ ÓPTIMO | I10: ESTADIO | J10: =COUNTIFS('Maestro infraestructura'!$A$2:$A$1052, I10) -> 12 | K10: =+COUNTIFS('Maestro infraestructura'!$A$2:$A$1051, I10,'Maestro infraestructura'!$K$2:$K$1051, $K$3) -> 12 | L10: =+COUNTIFS('Maestro infraestructura'!$A$2:$A$1051, I10,'Maestro infraestructura'!$K$2:$K$1051, $L$3) -> 0 | M10: =+COUNTIFS('Maestro infraestructura'!$A$2:$A$1051, I10,'Maestro infraestructura'!$K$2:$K$1051, $M$3) -> 0 | N10: =+COUNTIFS('Maestro infraestructura'!$A$2:$A$1051, I10,'Maestro infraestructura'!$K$2:$K$1051, $N$3) -> 0
A11: EDIFICIO PRINCIPAL | B11: OPERACIÓN | C11: 2 | D11: =COUNTIFS('Maestro infraestructura'!$A$2:$A$1052, A11,'Maestro infraestructura'!$X$2:$X$1052,B11,'Maestro infraestructura'!$Y$2:$Y$1052,C11) -> 345 | E11: =COUNTIFS('Maestro infraestructura'!$A$2:$A$1051, A11,'Maestro infraestructura'!$X$2:$X$1051,B11,'Maestro infraestructura'!$Y$2:$Y$1051,C11,'Maestro infraestructura'!$V$2:$V$1051, "AL DÍA") -> 345 | F11: =IF(D11=0,100%,IF(D11>0,E11/D11,0)) -> 1 | G11: =IF(F11=1, "✅ ÓPTIMO", IF(F11>=0.8, "⚠️ PRECAUCIÓN", "❌ CRÍTICO")) -> ✅ ÓPTIMO | I11: E. SUBTE | J11: =COUNTIFS('Maestro infraestructura'!$A$2:$A$1052, I11) -> 2 | K11: =+COUNTIFS('Maestro infraestructura'!$A$2:$A$1051, I11,'Maestro infraestructura'!$K$2:$K$1051, $K$3) -> 2 | L11: =+COUNTIFS('Maestro infraestructura'!$A$2:$A$1051, I11,'Maestro infraestructura'!$K$2:$K$1051, $L$3) -> 0 | M11: =+COUNTIFS('Maestro infraestructura'!$A$2:$A$1051, I11,'Maestro infraestructura'!$K$2:$K$1051, $M$3) -> 0 | N11: =+COUNTIFS('Maestro infraestructura'!$A$2:$A$1051, I11,'Maestro infraestructura'!$K$2:$K$1051, $N$3) -> 0
A12: EDIFICIO PRINCIPAL | B12: OPERACIÓN | C12: 3 | D12: =COUNTIFS('Maestro infraestructura'!$A$2:$A$1052, A12,'Maestro infraestructura'!$X$2:$X$1052,B12,'Maestro infraestructura'!$Y$2:$Y$1052,C12) -> 0 | E12: =COUNTIFS('Maestro infraestructura'!$A$2:$A$1051, A12,'Maestro infraestructura'!$X$2:$X$1051,B12,'Maestro infraestructura'!$Y$2:$Y$1051,C12,'Maestro infraestructura'!$V$2:$V$1051, "AL DÍA") -> 0 | F12: =IF(D12=0,100%,IF(D12>0,E12/D12,0)) -> 1 | G12: =IF(F12=1, "✅ ÓPTIMO", IF(F12>=0.8, "⚠️ PRECAUCIÓN", "❌ CRÍTICO")) -> ✅ ÓPTIMO | I12: E. LIMACHE | J12: =COUNTIFS('Maestro infraestructura'!$A$2:$A$1052, I12) -> 3 | K12: =+COUNTIFS('Maestro infraestructura'!$A$2:$A$1051, I12,'Maestro infraestructura'!$K$2:$K$1051, $K$3) -> 3 | L12: =+COUNTIFS('Maestro infraestructura'!$A$2:$A$1051, I12,'Maestro infraestructura'!$K$2:$K$1051, $L$3) -> 0 | M12: =+COUNTIFS('Maestro infraestructura'!$A$2:$A$1051, I12,'Maestro infraestructura'!$K$2:$K$1051, $M$3) -> 0 | N12: =+COUNTIFS('Maestro infraestructura'!$A$2:$A$1051, I12,'Maestro infraestructura'!$K$2:$K$1051, $N$3) -> 0
A13: EDIFICIO PRINCIPAL | B13: GENERAL | C13: 1 | D13: =COUNTIFS('Maestro infraestructura'!$A$2:$A$1052, A13,'Maestro infraestructura'!$X$2:$X$1052,B13,'Maestro infraestructura'!$Y$2:$Y$1052,C13) -> 42 | E13: =COUNTIFS('Maestro infraestructura'!$A$2:$A$1051, A13,'Maestro infraestructura'!$X$2:$X$1051,B13,'Maestro infraestructura'!$Y$2:$Y$1051,C13,'Maestro infraestructura'!$V$2:$V$1051, "AL DÍA") -> 42 | F13: =IF(D13=0,100%,IF(D13>0,E13/D13,0)) -> 1 | G13: =IF(F13=1, "✅ ÓPTIMO", IF(F13>=0.8, "⚠️ PRECAUCIÓN", "❌ CRÍTICO")) -> ✅ ÓPTIMO | I13: FERIENHEIM | J13: =COUNTIFS('Maestro infraestructura'!$A$2:$A$1052, I13) -> 4 | K13: =+COUNTIFS('Maestro infraestructura'!$A$2:$A$1051, I13,'Maestro infraestructura'!$K$2:$K$1051, $K$3) -> 4 | L13: =+COUNTIFS('Maestro infraestructura'!$A$2:$A$1051, I13,'Maestro infraestructura'!$K$2:$K$1051, $L$3) -> 0 | M13: =+COUNTIFS('Maestro infraestructura'!$A$2:$A$1051, I13,'Maestro infraestructura'!$K$2:$K$1051, $M$3) -> 0 | N13: =+COUNTIFS('Maestro infraestructura'!$A$2:$A$1051, I13,'Maestro infraestructura'!$K$2:$K$1051, $N$3) -> 0
A14: EDIFICIO PRINCIPAL | B14: GENERAL | C14: 2 | D14: =COUNTIFS('Maestro infraestructura'!$A$2:$A$1052, A14,'Maestro infraestructura'!$X$2:$X$1052,B14,'Maestro infraestructura'!$Y$2:$Y$1052,C14) -> 158 | E14: =COUNTIFS('Maestro infraestructura'!$A$2:$A$1051, A14,'Maestro infraestructura'!$X$2:$X$1051,B14,'Maestro infraestructura'!$Y$2:$Y$1051,C14,'Maestro infraestructura'!$V$2:$V$1051, "AL DÍA") -> 157 | F14: =IF(D14=0,100%,IF(D14>0,E14/D14,0)) -> 0.99367089 | G14: =IF(F14=1, "✅ ÓPTIMO", IF(F14>=0.8, "⚠️ PRECAUCIÓN", "❌ CRÍTICO")) -> ⚠️ PRECAUCIÓN
A15: EDIFICIO PRINCIPAL | B15: GENERAL | C15: 3 | D15: =COUNTIFS('Maestro infraestructura'!$A$2:$A$1052, A15,'Maestro infraestructura'!$X$2:$X$1052,B15,'Maestro infraestructura'!$Y$2:$Y$1052,C15) -> 0 | E15: =COUNTIFS('Maestro infraestructura'!$A$2:$A$1051, A15,'Maestro infraestructura'!$X$2:$X$1051,B15,'Maestro infraestructura'!$Y$2:$Y$1051,C15,'Maestro infraestructura'!$V$2:$V$1051, "AL DÍA") -> 0 | F15: =IF(D15=0,100%,IF(D15>0,E15/D15,0)) -> 1 | G15: =IF(F15=1, "✅ ÓPTIMO", IF(F15>=0.8, "⚠️ PRECAUCIÓN", "❌ CRÍTICO")) -> ✅ ÓPTIMO
A16: CICLO INICIAL | B16: SEGURIDAD | C16: 1 | D16: =COUNTIFS('Maestro infraestructura'!$A$2:$A$1052, A16,'Maestro infraestructura'!$X$2:$X$1052,B16,'Maestro infraestructura'!$Y$2:$Y$1052,C16) -> 4 | E16: =COUNTIFS('Maestro infraestructura'!$A$2:$A$1051, A16,'Maestro infraestructura'!$X$2:$X$1051,B16,'Maestro infraestructura'!$Y$2:$Y$1051,C16,'Maestro infraestructura'!$V$2:$V$1051, "AL DÍA") -> 4 | F16: =IF(D16=0,100%,IF(D16>0,E16/D16,0)) -> 1 | G16: =IF(F16=1, "✅ ÓPTIMO", IF(F16>=0.8, "⚠️ PRECAUCIÓN", "❌ CRÍTICO")) -> ✅ ÓPTIMO
A17: CICLO INICIAL | B17: SEGURIDAD | C17: 2 | D17: =COUNTIFS('Maestro infraestructura'!$A$2:$A$1052, A17,'Maestro infraestructura'!$X$2:$X$1052,B17,'Maestro infraestructura'!$Y$2:$Y$1052,C17) -> 13 | E17: =COUNTIFS('Maestro infraestructura'!$A$2:$A$1051, A17,'Maestro infraestructura'!$X$2:$X$1051,B17,'Maestro infraestructura'!$Y$2:$Y$1051,C17,'Maestro infraestructura'!$V$2:$V$1051, "AL DÍA") -> 13 | F17: =IF(D17=0,100%,IF(D17>0,E17/D17,0)) -> 1 | G17: =IF(F17=1, "✅ ÓPTIMO", IF(F17>=0.8, "⚠️ PRECAUCIÓN", "❌ CRÍTICO")) -> ✅ ÓPTIMO
A18: CICLO INICIAL | B18: SEGURIDAD | C18: 3 | D18: =COUNTIFS('Maestro infraestructura'!$A$2:$A$1052, A18,'Maestro infraestructura'!$X$2:$X$1052,B18,'Maestro infraestructura'!$Y$2:$Y$1052,C18) -> 0 | E18: =COUNTIFS('Maestro infraestructura'!$A$2:$A$1051, A18,'Maestro infraestructura'!$X$2:$X$1051,B18,'Maestro infraestructura'!$Y$2:$Y$1051,C18,'Maestro infraestructura'!$V$2:$V$1051, "AL DÍA") -> 0 | F18: =IF(D18=0,100%,IF(D18>0,E18/D18,0)) -> 1 | G18: =IF(F18=1, "✅ ÓPTIMO", IF(F18>=0.8, "⚠️ PRECAUCIÓN", "❌ CRÍTICO")) -> ✅ ÓPTIMO
A19: CICLO INICIAL | B19: LEGAL | C19: 1 | D19: =COUNTIFS('Maestro infraestructura'!$A$2:$A$1052, A19,'Maestro infraestructura'!$X$2:$X$1052,B19,'Maestro infraestructura'!$Y$2:$Y$1052,C19) -> 2 | E19: =COUNTIFS('Maestro infraestructura'!$A$2:$A$1051, A19,'Maestro infraestructura'!$X$2:$X$1051,B19,'Maestro infraestructura'!$Y$2:$Y$1051,C19,'Maestro infraestructura'!$V$2:$V$1051, "AL DÍA") -> 0 | F19: =IF(D19=0,100%,IF(D19>0,E19/D19,0)) -> 0 | G19: =IF(F19=1, "✅ ÓPTIMO", IF(F19>=0.8, "⚠️ PRECAUCIÓN", "❌ CRÍTICO")) -> ❌ CRÍTICO
A20: CICLO INICIAL | B20: LEGAL | C20: 2 | D20: =COUNTIFS('Maestro infraestructura'!$A$2:$A$1052, A20,'Maestro infraestructura'!$X$2:$X$1052,B20,'Maestro infraestructura'!$Y$2:$Y$1052,C20) -> 2 | E20: =COUNTIFS('Maestro infraestructura'!$A$2:$A$1051, A20,'Maestro infraestructura'!$X$2:$X$1051,B20,'Maestro infraestructura'!$Y$2:$Y$1051,C20,'Maestro infraestructura'!$V$2:$V$1051, "AL DÍA") -> 0 | F20: =IF(D20=0,100%,IF(D20>0,E20/D20,0)) -> 0 | G20: =IF(F20=1, "✅ ÓPTIMO", IF(F20>=0.8, "⚠️ PRECAUCIÓN", "❌ CRÍTICO")) -> ❌ CRÍTICO
A21: CICLO INICIAL | B21: LEGAL | C21: 3 | D21: =COUNTIFS('Maestro infraestructura'!$A$2:$A$1052, A21,'Maestro infraestructura'!$X$2:$X$1052,B21,'Maestro infraestructura'!$Y$2:$Y$1052,C21) -> 0 | E21: =COUNTIFS('Maestro infraestructura'!$A$2:$A$1051, A21,'Maestro infraestructura'!$X$2:$X$1051,B21,'Maestro infraestructura'!$Y$2:$Y$1051,C21,'Maestro infraestructura'!$V$2:$V$1051, "AL DÍA") -> 0 | F21: =IF(D21=0,100%,IF(D21>0,E21/D21,0)) -> 1 | G21: =IF(F21=1, "✅ ÓPTIMO", IF(F21>=0.8, "⚠️ PRECAUCIÓN", "❌ CRÍTICO")) -> ✅ ÓPTIMO
A22: CICLO INICIAL | B22: OPERACIÓN | C22: 1 | D22: =COUNTIFS('Maestro infraestructura'!$A$2:$A$1052, A22,'Maestro infraestructura'!$X$2:$X$1052,B22,'Maestro infraestructura'!$Y$2:$Y$1052,C22) -> 1 | E22: =COUNTIFS('Maestro infraestructura'!$A$2:$A$1051, A22,'Maestro infraestructura'!$X$2:$X$1051,B22,'Maestro infraestructura'!$Y$2:$Y$1051,C22,'Maestro infraestructura'!$V$2:$V$1051, "AL DÍA") -> 1 | F22: =IF(D22=0,100%,IF(D22>0,E22/D22,0)) -> 1 | G22: =IF(F22=1, "✅ ÓPTIMO", IF(F22>=0.8, "⚠️ PRECAUCIÓN", "❌ CRÍTICO")) -> ✅ ÓPTIMO
A23: CICLO INICIAL | B23: OPERACIÓN | C23: 2 | D23: =COUNTIFS('Maestro infraestructura'!$A$2:$A$1052, A23,'Maestro infraestructura'!$X$2:$X$1052,B23,'Maestro infraestructura'!$Y$2:$Y$1052,C23) -> 76 | E23: =COUNTIFS('Maestro infraestructura'!$A$2:$A$1051, A23,'Maestro infraestructura'!$X$2:$X$1051,B23,'Maestro infraestructura'!$Y$2:$Y$1051,C23,'Maestro infraestructura'!$V$2:$V$1051, "AL DÍA") -> 76 | F23: =IF(D23=0,100%,IF(D23>0,E23/D23,0)) -> 1 | G23: =IF(F23=1, "✅ ÓPTIMO", IF(F23>=0.8, "⚠️ PRECAUCIÓN", "❌ CRÍTICO")) -> ✅ ÓPTIMO
A24: CICLO INICIAL | B24: OPERACIÓN | C24: 3 | D24: =COUNTIFS('Maestro infraestructura'!$A$2:$A$1052, A24,'Maestro infraestructura'!$X$2:$X$1052,B24,'Maestro infraestructura'!$Y$2:$Y$1052,C24) -> 0 | E24: =COUNTIFS('Maestro infraestructura'!$A$2:$A$1051, A24,'Maestro infraestructura'!$X$2:$X$1051,B24,'Maestro infraestructura'!$Y$2:$Y$1051,C24,'Maestro infraestructura'!$V$2:$V$1051, "AL DÍA") -> 0 | F24: =IF(D24=0,100%,IF(D24>0,E24/D24,0)) -> 1 | G24: =IF(F24=1, "✅ ÓPTIMO", IF(F24>=0.8, "⚠️ PRECAUCIÓN", "❌ CRÍTICO")) -> ✅ ÓPTIMO
A25: CICLO INICIAL | B25: GENERAL | C25: 1 | D25: =COUNTIFS('Maestro infraestructura'!$A$2:$A$1052, A25,'Maestro infraestructura'!$X$2:$X$1052,B25,'Maestro infraestructura'!$Y$2:$Y$1052,C25) -> 14 | E25: =COUNTIFS('Maestro infraestructura'!$A$2:$A$1051, A25,'Maestro infraestructura'!$X$2:$X$1051,B25,'Maestro infraestructura'!$Y$2:$Y$1051,C25,'Maestro infraestructura'!$V$2:$V$1051, "AL DÍA") -> 14 | F25: =IF(D25=0,100%,IF(D25>0,E25/D25,0)) -> 1 | G25: =IF(F25=1, "✅ ÓPTIMO", IF(F25>=0.8, "⚠️ PRECAUCIÓN", "❌ CRÍTICO")) -> ✅ ÓPTIMO
... A49: SPIELGRUPPE | B49: GENERAL | C49: 1 | D49: =COUNTIFS('Maestro infraestructura'!$A$2:$A$1052, A49,'Maestro infraestructura'!$X$2:$X$1052,B49,'Maestro infraestructura'!$Y$2:$Y$1052,C49) -> 6 | E49: =COUNTIFS('Maestro infraestructura'!$A$2:$A$1051, A49,'Maestro infraestructura'!$X$2:$X$1051,B49,'Maestro infraestructura'!$Y$2:$Y$1051,C49,'Maestro infraestructura'!$V$2:$V$1051, "AL DÍA") -> 6 | F49: =IF(D49=0,100%,IF(D49>0,E49/D49,0)) -> 1 | G49: =IF(F49=1, "✅ ÓPTIMO", IF(F49>=0.8, "⚠️ PRECAUCIÓN", "❌ CRÍTICO")) -> ✅ ÓPTIMO
A50: SPIELGRUPPE | B50: GENERAL | C50: 2 | D50: =COUNTIFS('Maestro infraestructura'!$A$2:$A$1052, A50,'Maestro infraestructura'!$X$2:$X$1052,B50,'Maestro infraestructura'!$Y$2:$Y$1052,C50) -> 11 | E50: =COUNTIFS('Maestro infraestructura'!$A$2:$A$1051, A50,'Maestro infraestructura'!$X$2:$X$1051,B50,'Maestro infraestructura'!$Y$2:$Y$1051,C50,'Maestro infraestructura'!$V$2:$V$1051, "AL DÍA") -> 10 | F50: =IF(D50=0,100%,IF(D50>0,E50/D50,0)) -> 0.90909091 | G50: =IF(F50=1, "✅ ÓPTIMO", IF(F50>=0.8, "⚠️ PRECAUCIÓN", "❌ CRÍTICO")) -> ⚠️ PRECAUCIÓN | H50: xx
A51: SPIELGRUPPE | B51: GENERAL | C51: 3 | D51: =COUNTIFS('Maestro infraestructura'!$A$2:$A$1052, A51,'Maestro infraestructura'!$X$2:$X$1052,B51,'Maestro infraestructura'!$Y$2:$Y$1052,C51) -> 1 | E51: =COUNTIFS('Maestro infraestructura'!$A$2:$A$1051, A51,'Maestro infraestructura'!$X$2:$X$1051,B51,'Maestro infraestructura'!$Y$2:$Y$1051,C51,'Maestro infraestructura'!$V$2:$V$1051, "AL DÍA") -> 1 | F51: =IF(D51=0,100%,IF(D51>0,E51/D51,0)) -> 1 | G51: =IF(F51=1, "✅ ÓPTIMO", IF(F51>=0.8, "⚠️ PRECAUCIÓN", "❌ CRÍTICO")) -> ✅ ÓPTIMO
A52: CASINO | B52: SEGURIDAD | C52: 1 | D52: =COUNTIFS('Maestro infraestructura'!$A$2:$A$1052, A52,'Maestro infraestructura'!$X$2:$X$1052,B52,'Maestro infraestructura'!$Y$2:$Y$1052,C52) -> 2 | E52: =COUNTIFS('Maestro infraestructura'!$A$2:$A$1051, A52,'Maestro infraestructura'!$X$2:$X$1051,B52,'Maestro infraestructura'!$Y$2:$Y$1051,C52,'Maestro infraestructura'!$V$2:$V$1051, "AL DÍA") -> 2 | F52: =IF(D52=0,100%,IF(D52>0,E52/D52,0)) -> 1 | G52: =IF(F52=1, "✅ ÓPTIMO", IF(F52>=0.8, "⚠️ PRECAUCIÓN", "❌ CRÍTICO")) -> ✅ ÓPTIMO
A53: CASINO | B53: SEGURIDAD | C53: 2 | D53: =COUNTIFS('Maestro infraestructura'!$A$2:$A$1052, A53,'Maestro infraestructura'!$X$2:$X$1052,B53,'Maestro infraestructura'!$Y$2:$Y$1052,C53) -> 0 | E53: =COUNTIFS('Maestro infraestructura'!$A$2:$A$1051, A53,'Maestro infraestructura'!$X$2:$X$1051,B53,'Maestro infraestructura'!$Y$2:$Y$1051,C53,'Maestro infraestructura'!$V$2:$V$1051, "AL DÍA") -> 0 | F53: =IF(D53=0,100%,IF(D53>0,E53/D53,0)) -> 1 | G53: =IF(F53=1, "✅ ÓPTIMO", IF(F53>=0.8, "⚠️ PRECAUCIÓN", "❌ CRÍTICO")) -> ✅ ÓPTIMO
A54: CASINO | B54: SEGURIDAD | C54: 3 | D54: =COUNTIFS('Maestro infraestructura'!$A$2:$A$1052, A54,'Maestro infraestructura'!$X$2:$X$1052,B54,'Maestro infraestructura'!$Y$2:$Y$1052,C54) -> 0 | E54: =COUNTIFS('Maestro infraestructura'!$A$2:$A$1051, A54,'Maestro infraestructura'!$X$2:$X$1051,B54,'Maestro infraestructura'!$Y$2:$Y$1051,C54,'Maestro infraestructura'!$V$2:$V$1051, "AL DÍA") -> 0 | F54: =IF(D54=0,100%,IF(D54>0,E54/D54,0)) -> 1 | G54: =IF(F54=1, "✅ ÓPTIMO", IF(F54>=0.8, "⚠️ PRECAUCIÓN", "❌ CRÍTICO")) -> ✅ ÓPTIMO
A55: CASINO | B55: LEGAL | C55: 1 | D55: =COUNTIFS('Maestro infraestructura'!$A$2:$A$1052, A55,'Maestro infraestructura'!$X$2:$X$1052,B55,'Maestro infraestructura'!$Y$2:$Y$1052,C55) -> 2 | E55: =COUNTIFS('Maestro infraestructura'!$A$2:$A$1051, A55,'Maestro infraestructura'!$X$2:$X$1051,B55,'Maestro infraestructura'!$Y$2:$Y$1051,C55,'Maestro infraestructura'!$V$2:$V$1051, "AL DÍA") -> 0 | F55: =IF(D55=0,100%,IF(D55>0,E55/D55,0)) -> 0 | G55: =IF(F55=1, "✅ ÓPTIMO", IF(F55>=0.8, "⚠️ PRECAUCIÓN", "❌ CRÍTICO")) -> ❌ CRÍTICO
A56: CASINO | B56: LEGAL | C56: 2 | D56: =COUNTIFS('Maestro infraestructura'!$A$2:$A$1052, A56,'Maestro infraestructura'!$X$2:$X$1052,B56,'Maestro infraestructura'!$Y$2:$Y$1052,C56) -> 0 | E56: =COUNTIFS('Maestro infraestructura'!$A$2:$A$1051, A56,'Maestro infraestructura'!$X$2:$X$1051,B56,'Maestro infraestructura'!$Y$2:$Y$1051,C56,'Maestro infraestructura'!$V$2:$V$1051, "AL DÍA") -> 0 | F56: =IF(D56=0,100%,IF(D56>0,E56/D56,0)) -> 1 | G56: =IF(F56=1, "✅ ÓPTIMO", IF(F56>=0.8, "⚠️ PRECAUCIÓN", "❌ CRÍTICO")) -> ✅ ÓPTIMO
A57: CASINO | B57: LEGAL | C57: 3 | D57: =COUNTIFS('Maestro infraestructura'!$A$2:$A$1052, A57,'Maestro infraestructura'!$X$2:$X$1052,B57,'Maestro infraestructura'!$Y$2:$Y$1052,C57) -> 0 | E57: =COUNTIFS('Maestro infraestructura'!$A$2:$A$1051, A57,'Maestro infraestructura'!$X$2:$X$1051,B57,'Maestro infraestructura'!$Y$2:$Y$1051,C57,'Maestro infraestructura'!$V$2:$V$1051, "AL DÍA") -> 0 | F57: =IF(D57=0,100%,IF(D57>0,E57/D57,0)) -> 1 | G57: =IF(F57=1, "✅ ÓPTIMO", IF(F57>=0.8, "⚠️ PRECAUCIÓN", "❌ CRÍTICO")) -> ✅ ÓPTIMO
A58: CASINO | B58: OPERACIÓN | C58: 1 | D58: =COUNTIFS('Maestro infraestructura'!$A$2:$A$1052, A58,'Maestro infraestructura'!$X$2:$X$1052,B58,'Maestro infraestructura'!$Y$2:$Y$1052,C58) -> 0 | E58: =COUNTIFS('Maestro infraestructura'!$A$2:$A$1051, A58,'Maestro infraestructura'!$X$2:$X$1051,B58,'Maestro infraestructura'!$Y$2:$Y$1051,C58,'Maestro infraestructura'!$V$2:$V$1051, "AL DÍA") -> 0 | F58: =IF(D58=0,100%,IF(D58>0,E58/D58,0)) -> 1 | G58: =IF(F58=1, "✅ ÓPTIMO", IF(F58>=0.8, "⚠️ PRECAUCIÓN", "❌ CRÍTICO")) -> ✅ ÓPTIMO
A59: CASINO | B59: OPERACIÓN | C59: 2 | D59: =COUNTIFS('Maestro infraestructura'!$A$2:$A$1052, A59,'Maestro infraestructura'!$X$2:$X$1052,B59,'Maestro infraestructura'!$Y$2:$Y$1052,C59) -> 7 | E59: =COUNTIFS('Maestro infraestructura'!$A$2:$A$1051, A59,'Maestro infraestructura'!$X$2:$X$1051,B59,'Maestro infraestructura'!$Y$2:$Y$1051,C59,'Maestro infraestructura'!$V$2:$V$1051, "AL DÍA") -> 7 | F59: =IF(D59=0,100%,IF(D59>0,E59/D59,0)) -> 1 | G59: =IF(F59=1, "✅ ÓPTIMO", IF(F59>=0.8, "⚠️ PRECAUCIÓN", "❌ CRÍTICO")) -> ✅ ÓPTIMO
A60: CASINO | B60: OPERACIÓN | C60: 3 | D60: =COUNTIFS('Maestro infraestructura'!$A$2:$A$1052, A60,'Maestro infraestructura'!$X$2:$X$1052,B60,'Maestro infraestructura'!$Y$2:$Y$1052,C60) -> 0 | E60: =COUNTIFS('Maestro infraestructura'!$A$2:$A$1051, A60,'Maestro infraestructura'!$X$2:$X$1051,B60,'Maestro infraestructura'!$Y$2:$Y$1051,C60,'Maestro infraestructura'!$V$2:$V$1051, "AL DÍA") -> 0 | F60: =IF(D60=0,100%,IF(D60>0,E60/D60,0)) -> 1 | G60: =IF(F60=1, "✅ ÓPTIMO", IF(F60>=0.8, "⚠️ PRECAUCIÓN", "❌ CRÍTICO")) -> ✅ ÓPTIMO
A61: CASINO | B61: GENERAL | C61: 1 | D61: =COUNTIFS('Maestro infraestructura'!$A$2:$A$1052, A61,'Maestro infraestructura'!$X$2:$X$1052,B61,'Maestro infraestructura'!$Y$2:$Y$1052,C61) -> 2 | E61: =COUNTIFS('Maestro infraestructura'!$A$2:$A$1051, A61,'Maestro infraestructura'!$X$2:$X$1051,B61,'Maestro infraestructura'!$Y$2:$Y$1051,C61,'Maestro infraestructura'!$V$2:$V$1051, "AL DÍA") -> 2 | F61: =IF(D61=0,100%,IF(D61>0,E61/D61,0)) -> 1 | G61: =IF(F61=1, "✅ ÓPTIMO", IF(F61>=0.8, "⚠️ PRECAUCIÓN", "❌ CRÍTICO")) -> ✅ ÓPTIMO
A62: CASINO | B62: GENERAL | C62: 2 | D62: =COUNTIFS('Maestro infraestructura'!$A$2:$A$1052, A62,'Maestro infraestructura'!$X$2:$X$1052,B62,'Maestro infraestructura'!$Y$2:$Y$1052,C62) -> 0 | E62: =COUNTIFS('Maestro infraestructura'!$A$2:$A$1051, A62,'Maestro infraestructura'!$X$2:$X$1051,B62,'Maestro infraestructura'!$Y$2:$Y$1051,C62,'Maestro infraestructura'!$V$2:$V$1051, "AL DÍA") -> 0 | F62: =IF(D62=0,100%,IF(D62>0,E62/D62,0)) -> 1 | G62: =IF(F62=1, "✅ ÓPTIMO", IF(F62>=0.8, "⚠️ PRECAUCIÓN", "❌ CRÍTICO")) -> ✅ ÓPTIMO
... A123: FERIENHEIM | B123: GENERAL | C123: 3 | D123: =COUNTIFS('Maestro infraestructura'!$A$2:$A$1052, A123,'Maestro infraestructura'!$X$2:$X$1052,B123,'Maestro infraestructura'!$Y$2:$Y$1052,C123) -> 0 | E123: =COUNTIFS('Maestro infraestructura'!$A$2:$A$1051, A123,'Maestro infraestructura'!$X$2:$X$1051,B123,'Maestro infraestructura'!$Y$2:$Y$1051,C123,'Maestro infraestructura'!$V$2:$V$1051, "AL DÍA") -> 0 | F123: =IF(D123=0,100%,IF(D123>0,E123/D123,0)) -> 1 | G123: =IF(F123=1, "✅ ÓPTIMO", IF(F123>=0.8, "⚠️ PRECAUCIÓN", "❌ CRÍTICO")) -> ✅ ÓPTIMO
D124: =SUM(D4:D123) -> 1051 | E124: =SUM(E4:E123) -> 1001 | F124: =+E124/D124 -> 0.95242626 | G124: =IF(F124=1, "✅ ÓPTIMO", IF(F124>=0.8, "⚠️ PRECAUCIÓN", "❌ CRÍTICO")) -> ⚠️ PRECAUCIÓN | J124: =SUM(J4:J123) -> 1051

Sheet Maestro infraestructura
A1: Edificio | B1: Área / Nivel | C1: Espacio | D1: Categoría | E1: Sub Categoría | F1: Tipo de Equipo | G1: Fecha Adquisición | H1: Años Vida útil | I1: Años de uso | J1: Estado | K1: Cambio/informe/ presupuesto | L1: Marca | M1: Modelo | N1: N° Serie | O1: Potencia / Capacidad | P1: Frecuencia de Mantención | Q1: Días | R1: Responsable | S1: Fecha de Último Mantenimiento | T1: Fecha de Próximo Mantenimiento | U1: Días Restantes | V1: Estado | W1: Observaciones / Estado Actual | X1: Clasificación | Y1: Prioridad | Z1: Observación 1
A2: CASINO | B2: 1° Piso | C2: Pasillo trasero | D2: Equipo | E2: Climatización | F2: Calefont | G2: 2026 | H2: 15 | I2: =YEAR(TODAY())-G2 -> 0 | J2: 3 | K2: =IF(J2=1,"Cambiar",IF(J2=2,"Presupuestar",IF(H2=0,"Activo",IF(G2+H2<YEAR(TODAY()),"Cambiar o Inspección externa",IF(G2+H2-1<YEAR(TODAY()),"Presupuestar","Activo"))))) -> Activo | L2: SPLENDID | M2: IONIZ | O2: 16 LT | P2: Anual | Q2: 365 | R2: Empresa externa clima - RyR | S2: 46146 | T2: =+S2+Q2 -> 46511 | U2: =T2-TODAY() -> 250 | V2: =IF(U2<0, "VENCIDO", "AL DÍA") -> AL DÍA | W2: Operativo | X2: OPERACIÓN | Y2: 2 | Z2: Renovación sello verde SEC febrero 2027
A3: CASINO | B3: 1° Piso | C3: Acceso a Casino | D3: Infraestructura | F3: Terraza metálica y madera | G3: 2023 | H3: 20 | I3: =YEAR(TODAY())-G3 -> 3 | J3: 3 | K3: =IF(J3=1,"Cambiar",IF(J3=2,"Presupuestar",IF(H3=0,"Activo",IF(G3+H3<YEAR(TODAY()),"Cambiar o Inspección externa",IF(G3+H3-1<YEAR(TODAY()),"Presupuestar","Activo"))))) -> Activo | L3: N/A | M3: N/A | N3: N/A | P3: Anual | Q3: 365 | R3: Operaciones DSV | S3: 46073 | T3: =+S3+Q3 -> 46438 | U3: =T3-TODAY() -> 177 | V3: =IF(U3<0, "VENCIDO", "AL DÍA") -> AL DÍA | W3: Operativo | X3: GENERAL | Y3: 1 | Z3: Área de esparcimiento que requiere mantenimiento preventivo.
A4: CASINO | B4: 1° Piso | C4: Acceso a Casino | D4: Equipo | E4: Tablero Eléctrico | F4: Tablero eléctrico principal | G4: 2018 | H4: 40 | I4: =YEAR(TODAY())-G4 -> 8 | J4: 3 | K4: =IF(J4=1,"Cambiar",IF(J4=2,"Presupuestar",IF(H4=0,"Activo",IF(G4+H4<YEAR(TODAY()),"Cambiar o Inspección externa",IF(G4+H4-1<YEAR(TODAY()),"Presupuestar","Activo"))))) -> Activo | L4: N/A | M4: N/A | N4: N/A | P4: Anual | Q4: 365 | R4: Empresa externa | S4: 46037 | T4: =+S4+Q4 -> 46402 | U4: =T4-TODAY() -> 141 | V4: =IF(U4<0, "VENCIDO", "AL DÍA") -> AL DÍA | W4: Operativo | X4: SEGURIDAD | Y4: 1 | Z4: Distribución primaria de energía; vital para la integridad de la red.
A5: CASINO | B5: 1° Piso | C5: Cafetería | D5: Equipo | E5: Tablero Eléctrico | F5: Tablero eléctrico secundario | G5: 2018 | H5: 40 | I5: =YEAR(TODAY())-G5 -> 8 | J5: 3 | K5: =IF(J5=1,"Cambiar",IF(J5=2,"Presupuestar",IF(H5=0,"Activo",IF(G5+H5<YEAR(TODAY()),"Cambiar o Inspección externa",IF(G5+H5-1<YEAR(TODAY()),"Presupuestar","Activo"))))) -> Activo | L5: N/A | M5: N/A | N5: N/A | P5: Anual | Q5: 365 | R5: Empresa externa | S5: 46037 | T5: =+S5+Q5 -> 46402 | U5: =T5-TODAY() -> 141 | V5: =IF(U5<0, "VENCIDO", "AL DÍA") -> AL DÍA | W5: Operativo | X5: OPERACIÓN | Y5: 2 | Z5: Distribución local de energía en sectores específicos.
A6: CASINO | B6: 1° Piso | C6: 1° Piso | D6: Infraestructura | F6: Pintura de paredes interior | G6: 2000 | H6: 0 | I6: =YEAR(TODAY())-G6 -> 26 | J6: 3 | K6: =IF(J6=1,"Cambiar",IF(J6=2,"Presupuestar",IF(H6=0,"Activo",IF(G6+H6<YEAR(TODAY()),"Cambiar o Inspección externa",IF(G6+H6-1<YEAR(TODAY()),"Presupuestar","Activo"))))) -> Activo | L6: N/A | M6: N/A | N6: N/A | P6: 2 años | Q6: =365*2 -> 730 | R6: Operaciones DSV | S6: 45840 | T6: =+S6+Q6 -> 46570 | U6: =T6-TODAY() -> 309 | V6: =IF(U6<0, "VENCIDO", "AL DÍA") -> AL DÍA | W6: Operativo | X6: GENERAL | Y6: 3
A7: CASINO | B7: 1° Piso | C7: 1° Piso | D7: Infraestructura | F7: Pintura fachadas | G7: 2000 | H7: 0 | I7: =YEAR(TODAY())-G7 -> 26 | J7: 3 | K7: =IF(J7=1,"Cambiar",IF(J7=2,"Presupuestar",IF(H7=0,"Activo",IF(G7+H7<YEAR(TODAY()),"Cambiar o Inspección externa",IF(G7+H7-1<YEAR(TODAY()),"Presupuestar","Activo"))))) -> Activo | L7: N/A | M7: N/A | N7: N/A | P7: 5 años | Q7: =5*365 -> 1825 | R7: Operaciones DSV | S7: 45301 | T7: =+S7+Q7 -> 47126 | U7: =T7-TODAY() -> 865 | V7: =IF(U7<0, "VENCIDO", "AL DÍA") -> AL DÍA | W7: Operativo | X7: GENERAL | Y7: 1 | Z7: Lavado de pared de siding pvc
A8: CASINO | B8: 1° Piso | C8: Edificio | D8: Infraestructura | F8: Techumbre Casino | G8: 2000 | H8: 25 | I8: =YEAR(TODAY())-G8 -> 26 | J8: 3 | K8: =IF(J8=1,"Cambiar",IF(J8=2,"Presupuestar",IF(H8=0,"Activo",IF(G8+H8<YEAR(TODAY()),"Cambiar o Inspección externa",IF(G8+H8-1<YEAR(TODAY()),"Presupuestar","Activo"))))) -> Cambiar o Inspección externa | L8: N/A | M8: N/A | N8: N/A | P8: 3-4 años | Q8: =365*3.5 -> 1277.5 | R8: Operaciones DSV | S8: 45672 | T8: =+S8+Q8 -> 46949.5 | U8: =T8-TODAY() -> 688.5 | V8: =IF(U8<0, "VENCIDO", "AL DÍA") -> AL DÍA | W8: Operativo | X8: SEGURIDAD | Y8: 1 | Z8: Cubierta estructural /inspección visual
A9: CASINO | B9: 1° Piso | C9: Cocina | D9: Equipo | F9: Horno Industrial doble cámara | G9: 2024 | H9: 10 | I9: =YEAR(TODAY())-G9 -> 2 | J9: 3 | K9: =IF(J9=1,"Cambiar",IF(J9=2,"Presupuestar",IF(H9=0,"Activo",IF(G9+H9<YEAR(TODAY()),"Cambiar o Inspección externa",IF(G9+H9-1<YEAR(TODAY()),"Presupuestar","Activo"))))) -> Activo | P9: 1 años | Q9: 365 | R9: Externo Mantención Integral | S9: 46157 | T9: =+S9+Q9 -> 46522 | U9: =T9-TODAY() -> 261 | V9: =IF(U9<0, "VENCIDO", "AL DÍA") -> AL DÍA | W9: Operativo | X9: OPERACIÓN | Y9: 2 | Z9: Mantencion en Mayo
A10: CASINO | B10: 1° Piso | C10: Cocina | D10: Equipo | F10: Cocina Industrial 1 | G10: 2026 | H10: 10 | I10: =YEAR(TODAY())-G10 -> 0 | J10: 3 | K10: =IF(J10=1,"Cambiar",IF(J10=2,"Presupuestar",IF(H10=0,"Activo",IF(G10+H10<YEAR(TODAY()),"Cambiar o Inspección externa",IF(G10+H10-1<YEAR(TODAY()),"Presupuestar","Activo"))))) -> Activo | P10: 1 años | Q10: 365 | R10: Externo Mantención Integral | S10: 46157 | T10: =+S10+Q10 -> 46522 | U10: =T10-TODAY() -> 261 | V10: =IF(U10<0, "VENCIDO", "AL DÍA") -> AL DÍA | W10: Operativo | X10: OPERACIÓN | Y10: 2 | Z10: Se renovó en junio
A11: CASINO | B11: 1° Piso | C11: Cocina | D11: Equipo | F11: Cocina Industrial 2 | G11: 2024 | H11: 10 | I11: =YEAR(TODAY())-G11 -> 2 | J11: 3 | K11: =IF(J11=1,"Cambiar",IF(J11=2,"Presupuestar",IF(H11=0,"Activo",IF(G11+H11<YEAR(TODAY()),"Cambiar o Inspección externa",IF(G11+H11-1<YEAR(TODAY()),"Presupuestar","Activo"))))) -> Activo | P11: 1 años | Q11: 365 | R11: Externo Mantención Integral | S11: 46157 | T11: =+S11+Q11 -> 46522 | U11: =T11-TODAY() -> 261 | V11: =IF(U11<0, "VENCIDO", "AL DÍA") -> AL DÍA | W11: Operativo | X11: OPERACIÓN | Y11: 2 | Z11: Equipamiento clave para el servicio de alimentación de alumnos.
A12: CASINO | B12: 1° Piso | C12: Cocina | D12: Equipo | F12: Campana de extracción | G12: 2000 | H12: 30 | I12: =YEAR(TODAY())-G12 -> 26 | J12: 3 | K12: =IF(J12=1,"Cambiar",IF(J12=2,"Presupuestar",IF(H12=0,"Activo",IF(G12+H12<YEAR(TODAY()),"Cambiar o Inspección externa",IF(G12+H12-1<YEAR(TODAY()),"Presupuestar","Activo"))))) -> Activo | P12: 1 años | Q12: 365 | R12: Externo Mantención Integral | S12: 46157 | T12: =+S12+Q12 -> 46522 | U12: =T12-TODAY() -> 261 | V12: =IF(U12<0, "VENCIDO", "AL DÍA") -> AL DÍA | W12: Operativo | X12: OPERACIÓN | Y12: 2 | Z12: Vital para la ventilación y seguridad en áreas de cocina.
A13: CASINO | B13: Piso zócalo | C13: Werken 1 | D13: Equipo | E13: Tablero Eléctrico | F13: Tablero eléctrico secundario | G13: 2000 | H13: 40 | I13: =YEAR(TODAY())-G13 -> 26 | J13: 3 | K13: =IF(J13=1,"Cambiar",IF(J13=2,"Presupuestar",IF(H13=0,"Activo",IF(G13+H13<YEAR(TODAY()),"Cambiar o Inspección externa",IF(G13+H13-1<YEAR(TODAY()),"Presupuestar","Activo"))))) -> Activo | L13: N/A | M13: N/A | N13: N/A | O13: 20 A | P13: Anual | Q13: 365 | R13: Empresa externa | S13: 46037 | T13: =+S13+Q13 -> 46402 | U13: =T13-TODAY() -> 141 | V13: =IF(U13<0, "VENCIDO", "AL DÍA") -> AL DÍA | W13: Operativo | X13: OPERACIÓN | Y13: 2 | Z13: Distribución local de energía en sectores específicos.
A14: CASINO | B14: Piso zócalo | C14: Zócalo | D14: Infraestructura | E14: Camarines | F14: Camarín Hombre | G14: 2000 | H14: 0 | I14: =YEAR(TODAY())-G14 -> 26 | J14: 3 | K14: =IF(J14=1,"Cambiar",IF(J14=2,"Presupuestar",IF(H14=0,"Activo",IF(G14+H14<YEAR(TODAY()),"Cambiar o Inspección externa",IF(G14+H14-1<YEAR(TODAY()),"Presupuestar","Activo"))))) -> Activo | L14: N/A | M14: N/A | N14: N/A | O14: 2 duchas | P14: Mensual | Q14: 30 | R14: Operaciones DSV | S14: 46228 | T14: =+S14+Q14 -> 46258 | U14: =T14-TODAY() -> -3 | V14: =IF(U14<0, "VENCIDO", "AL DÍA") -> VENCIDO | W14: Operativo | X14: LEGAL | Y14: 1 | Z14: Normativa deportiva y de salud para actividades físicas.
A15: CASINO | B15: Piso zócalo | C15: Zócalo | D15: Infraestructura | E15: Camarines | F15: Camarín Mujeres | G15: 2000 | H15: 0 | I15: =YEAR(TODAY())-G15 -> 26 | J15: 3 | K15: =IF(J15=1,"Cambiar",IF(J15=2,"Presupuestar",IF(H15=0,"Activo",IF(G15+H15<YEAR(TODAY()),"Cambiar o Inspección externa",IF(G15+H15-1<YEAR(TODAY()),"Presupuestar","Activo"))))) -> Activo | L15: N/A | M15: N/A | N15: N/A | O15: 2 duchas | P15: Mensual | Q15: 30 | R15: Operaciones DSV | S15: 46228 | T15: =+S15+Q15 -> 46258 | U15: =T15-TODAY() -> -3 | V15: =IF(U15<0, "VENCIDO", "AL DÍA") -> VENCIDO | W15: Operativo | X15: LEGAL | Y15: 1 | Z15: Normativa deportiva y de salud para actividades físicas.
A16: CICLO INICIAL | B16: 1° Piso | C16: Sala caldera NB | D16: Equipo | E16: Climatización | F16: Caldera | G16: 2013 | H16: 15 | I16: =YEAR(TODAY())-G16 -> 13 | J16: 3 | K16: =IF(J16=1,"Cambiar",IF(J16=2,"Presupuestar",IF(H16=0,"Activo",IF(G16+H16<YEAR(TODAY()),"Cambiar o Inspección externa",IF(G16+H16-1<YEAR(TODAY()),"Presupuestar","Activo"))))) -> Activo | L16: ACV | M16: PRESTIGE 75 | N16: 04S1BO0751 | O16: 69.9 kW | P16: Anual | Q16: 365 | R16: Empresa externa clima - RyR | S16: 46198 | T16: =+S16+Q16 -> 46563 | U16: =T16-TODAY() -> 302 | V16: =IF(U16<0, "VENCIDO", "AL DÍA") -> AL DÍA | W16: Operativo | X16: OPERACIÓN | Y16: 1 | Z16: Generador de calor central; su falla detiene el sistema de calefacción.
A17: CICLO INICIAL | B17: 1° Piso | D17: Equipo | E17: Climatización | F17: Radiadores | G17: 2013 | H17: 20 | I17: =YEAR(TODAY())-G17 -> 13 | J17: 3 | K17: =IF(J17=1,"Cambiar",IF(J17=2,"Presupuestar",IF(H17=0,"Activo",IF(G17+H17<YEAR(TODAY()),"Cambiar o Inspección externa",IF(G17+H17-1<YEAR(TODAY()),"Presupuestar","Activo"))))) -> Activo | L17: ANWO | P17: Anual | Q17: 365 | R17: Empresa externa clima - RyR | S17: 46198 | T17: =+S17+Q17 -> 46563 | U17: =T17-TODAY() -> 302 | V17: =IF(U17<0, "VENCIDO", "AL DÍA") -> AL DÍA | W17: Operativo | X17: GENERAL | Y17: 1 | Z17: Emisores de calor (el sistema principal es Operación).
A18: CICLO INICIAL | B18: 1° Piso | C18: Patio principal | D18: Infraestructura | F18: Techumbre metálica patio central CI | G18: 2023 | H18: 25 | I18: =YEAR(TODAY())-G18 -> 3 | J18: 3 | K18: =IF(J18=1,"Cambiar",IF(J18=2,"Presupuestar",IF(H18=0,"Activo",IF(G18+H18<YEAR(TODAY()),"Cambiar o Inspección externa",IF(G18+H18-1<YEAR(TODAY()),"Presupuestar","Activo"))))) -> Activo | L18: N/A | M18: N/A | N18: N/A | O18: 17 m x 33 m | P18: 3-4 años | Q18: =365*3.5 -> 1277.5 | R18: Operaciones DSV | S18: 46198 | T18: =+S18+Q18 -> 47475.5 | U18: =T18-TODAY() -> 1214.5 | V18: =IF(U18<0, "VENCIDO", "AL DÍA") -> AL DÍA | W18: Operativo | X18: SEGURIDAD | Y18: 1 | Z18: Estructura de gran envergadura en zonas de alto tránsito de alumnos.
A19: CICLO INICIAL | B19: 1° Piso | C19: Estac. Subterráneo | D19: Equipo | E19: Tablero Eléctrico | F19: Tablero eléctrico principal | G19: 2013 | H19: 40 | I19: =YEAR(TODAY())-G19 -> 13 | J19: 3 | K19: =IF(J19=1,"Cambiar",IF(J19=2,"Presupuestar",IF(H19=0,"Activo",IF(G19+H19<YEAR(TODAY()),"Cambiar o Inspección externa",IF(G19+H19-1<YEAR(TODAY()),"Presupuestar","Activo"))))) -> Activo | L19: N/A | M19: N/A | N19: N/A | O19: 100 A | P19: Anual | Q19: 365 | R19: Empresa externa | S19: 46198 | T19: =+S19+Q19 -> 46563 | U19: =T19-TODAY() -> 302 | V19: =IF(U19<0, "VENCIDO", "AL DÍA") -> AL DÍA | W19: Operativo | X19: SEGURIDAD | Y19: 1 | Z19: Distribución primaria de energía; vital para la integridad de la red.
A20: CICLO INICIAL | B20: 1° Piso | C20: Patio de Juegos | D20: Equipo | E20: Tablero Eléctrico | F20: Tablero eléctrico de derivación | G20: 2013 | H20: 40 | I20: =YEAR(TODAY())-G20 -> 13 | J20: 3 | K20: =IF(J20=1,"Cambiar",IF(J20=2,"Presupuestar",IF(H20=0,"Activo",IF(G20+H20<YEAR(TODAY()),"Cambiar o Inspección externa",IF(G20+H20-1<YEAR(TODAY()),"Presupuestar","Activo"))))) -> Activo | L20: N/A | M20: N/A | N20: N/A | P20: Anual | Q20: 365 | R20: Empresa externa | S20: 46198 | T20: =+S20+Q20 -> 46563 | U20: =T20-TODAY() -> 302 | V20: =IF(U20<0, "VENCIDO", "AL DÍA") -> AL DÍA | W20: Operativo | X20: SEGURIDAD | Y20: 1 | Z20: Distribución primaria de energía; vital para la integridad de la red.
A21: CICLO INICIAL | B21: 1° Piso | C21: 1° Piso | D21: Infraestructura | E21: Baño | F21: Baño adultos funcionarios | G21: 2013 | H21: 0 | I21: =YEAR(TODAY())-G21 -> 13 | J21: 3 | K21: =IF(J21=1,"Cambiar",IF(J21=2,"Presupuestar",IF(H21=0,"Activo",IF(G21+H21<YEAR(TODAY()),"Cambiar o Inspección externa",IF(G21+H21-1<YEAR(TODAY()),"Presupuestar","Activo"))))) -> Activo | L21: N/A | M21: N/A | N21: N/A | P21: Mensual | Q21: 30 | R21: Operaciones DSV | S21: 46228 | T21: =+S21+Q21 -> 46258 | U21: =T21-TODAY() -> -3 | V21: =IF(U21<0, "VENCIDO", "AL DÍA") -> VENCIDO | W21: Operativo | X21: LEGAL | Y21: 1
A22: CICLO INICIAL | B22: 1° Piso | C22: 1° Piso | D22: Infraestructura | E22: Baño | F22: Baño discapacitado | G22: 2013 | H22: 0 | I22: =YEAR(TODAY())-G22 -> 13 | J22: 3 | K22: =IF(J22=1,"Cambiar",IF(J22=2,"Presupuestar",IF(H22=0,"Activo",IF(G22+H22<YEAR(TODAY()),"Cambiar o Inspección externa",IF(G22+H22-1<YEAR(TODAY()),"Presupuestar","Activo"))))) -> Activo | L22: N/A | M22: N/A | N22: N/A | O22: 1 WC | P22: Mensual | Q22: 30 | R22: Operaciones DSV | S22: 46228 | T22: =+S22+Q22 -> 46258 | U22: =T22-TODAY() -> -3 | V22: =IF(U22<0, "VENCIDO", "AL DÍA") -> VENCIDO | W22: Operativo | X22: LEGAL | Y22: 1 | Z22: Cumplimiento de accesibilidad universal y seguridad para personas con movilidad reducida.
A23: CICLO INICIAL | B23: 1° Piso | C23: 1° Piso | D23: Infraestructura | E23: Baño | F23: Baño alumnos varones | G23: 2013 | H23: 0 | I23: =YEAR(TODAY())-G23 -> 13 | J23: 3 | K23: =IF(J23=1,"Cambiar",IF(J23=2,"Presupuestar",IF(H23=0,"Activo",IF(G23+H23<YEAR(TODAY()),"Cambiar o Inspección externa",IF(G23+H23-1<YEAR(TODAY()),"Presupuestar","Activo"))))) -> Activo | L23: N/A | M23: N/A | N23: N/A | O23: 2 | P23: Mensual | Q23: 30 | R23: Operaciones DSV | S23: 46228 | T23: =+S23+Q23 -> 46258 | U23: =T23-TODAY() -> -3 | V23: =IF(U23<0, "VENCIDO", "AL DÍA") -> VENCIDO | W23: Operativo | X23: LEGAL | Y23: 2
A24: CICLO INICIAL | B24: 1° Piso | C24: 1° Piso | D24: Infraestructura | E24: Baño | F24: Baño alumnos mujeres | G24: 2013 | H24: 0 | I24: =YEAR(TODAY())-G24 -> 13 | J24: 3 | K24: =IF(J24=1,"Cambiar",IF(J24=2,"Presupuestar",IF(H24=0,"Activo",IF(G24+H24<YEAR(TODAY()),"Cambiar o Inspección externa",IF(G24+H24-1<YEAR(TODAY()),"Presupuestar","Activo"))))) -> Activo | L24: N/A | M24: N/A | N24: N/A | P24: Mensual | Q24: 30 | R24: Operaciones DSV | S24: 46228 | T24: =+S24+Q24 -> 46258 | U24: =T24-TODAY() -> -3 | V24: =IF(U24<0, "VENCIDO", "AL DÍA") -> VENCIDO | W24: Operativo | X24: LEGAL | Y24: 2
A25: CICLO INICIAL | B25: 1° Piso | C25: 1° Piso | D25: Infraestructura | F25: Pintura de paredes interior | G25: 2013 | H25: 0 | I25: =YEAR(TODAY())-G25 -> 13 | J25: 3 | K25: =IF(J25=1,"Cambiar",IF(J25=2,"Presupuestar",IF(H25=0,"Activo",IF(G25+H25<YEAR(TODAY()),"Cambiar o Inspección externa",IF(G25+H25-1<YEAR(TODAY()),"Presupuestar","Activo"))))) -> Activo | L25: N/A | M25: N/A | N25: N/A | P25: 3 años | Q25: =365*3 -> 1095 | R25: Operaciones DSV | S25: 46198 | T25: =+S25+Q25 -> 47293 | U25: =T25-TODAY() -> 1032 | V25: =IF(U25<0, "VENCIDO", "AL DÍA") -> AL DÍA | W25: Operativo | X25: GENERAL | Y25: 3
A26: CICLO INICIAL | B26: 1° Piso | C26: 1° Piso | D26: Infraestructura | F26: Siding | G26: 2013 | H26: 25 | I26: =YEAR(TODAY())-G26 -> 13 | J26: 3 | K26: =IF(J26=1,"Cambiar",IF(J26=2,"Presupuestar",IF(H26=0,"Activo",IF(G26+H26<YEAR(TODAY()),"Cambiar o Inspección externa",IF(G26+H26-1<YEAR(TODAY()),"Presupuestar","Activo"))))) -> Activo | L26: N/A | M26: N/A | N26: N/A | P26: 5 años | Q26: =5*365 -> 1825 | R26: Operaciones DSV | S26: 46198 | T26: =+S26+Q26 -> 48023 | U26: =T26-TODAY() -> 1762 | V26: =IF(U26<0, "VENCIDO", "AL DÍA") -> AL DÍA | W26: Operativo | X26: GENERAL | Y26: 2 | Z26: Lavado de pared de siding pvc
A27: CICLO INICIAL | B27: 1° Piso | C27: Edificio | D27: Infraestructura | F27: Techumbre Ciclo Inicial | G27: 2013 | H27: 25 | I27: =YEAR(TODAY())-G27 -> 13 | J27: 3 | K27: =IF(J27=1,"Cambiar",IF(J27=2,"Presupuestar",IF(H27=0,"Activo",IF(G27+H27<YEAR(TODAY()),"Cambiar o Inspección externa",IF(G27+H27-1<YEAR(TODAY()),"Presupuestar","Activo"))))) -> Activo | L27: N/A | M27: N/A | N27: N/A | P27: 3-4 años | Q27: =365*3.5 -> 1277.5 | R27: Operaciones DSV | S27: 46198 | T27: =+S27+Q27 -> 47475.5 | U27: =T27-TODAY() -> 1214.5 | V27: =IF(U27<0, "VENCIDO", "AL DÍA") -> AL DÍA | W27: Operativo | X27: SEGURIDAD | Y27: 1 | Z27: Cubierta estructural
A28: CICLO INICIAL | B28: 1° Piso | C28: K1A | D28: Infraestructura | F28: Ventanas | G28: 2013 | H28: 0 | I28: =YEAR(TODAY())-G28 -> 13 | J28: 3 | K28: =IF(J28=1,"Cambiar",IF(J28=2,"Presupuestar",IF(H28=0,"Activo",IF(G28+H28<YEAR(TODAY()),"Cambiar o Inspección externa",IF(G28+H28-1<YEAR(TODAY()),"Presupuestar","Activo"))))) -> Activo | L28: N/A | M28: N/A | N28: N/A | P28: Anual | Q28: 365 | R28: Empresa externa | S28: 46198 | T28: =+S28+Q28 -> 46563 | U28: =T28-TODAY() -> 302 | V28: =IF(U28<0, "VENCIDO", "AL DÍA") -> AL DÍA | W28: Operativo | X28: SEGURIDAD | Y28: 2 | Z28: Distribución primaria de energía; vital para la integridad de la red.
A29: CICLO INICIAL | B29: 1° Piso | C29: K1A | D29: Infraestructura | E29: Climatización | F29: Radiadores | G29: 2013 | H29: 20 | I29: =YEAR(TODAY())-G29 -> 13 | J29: 3 | K29: =IF(J29=1,"Cambiar",IF(J29=2,"Presupuestar",IF(H29=0,"Activo",IF(G29+H29<YEAR(TODAY()),"Cambiar o Inspección externa",IF(G29+H29-1<YEAR(TODAY()),"Presupuestar","Activo"))))) -> Activo | L29: SIN INFORMACIÓN | P29: Anual | Q29: 365 | R29: Operaciones DSV | S29: 46198 | T29: =+S29+Q29 -> 46563 | U29: =T29-TODAY() -> 302 | V29: =IF(U29<0, "VENCIDO", "AL DÍA") -> AL DÍA | W29: Operativo | X29: GENERAL | Y29: 1 | Z29: Emisores de calor (el sistema principal es Operación).
A30: CICLO INICIAL | B30: 1° Piso | C30: K1A | D30: Infraestructura | F30: Piso | G30: 2013 | H30: 0 | I30: =YEAR(TODAY())-G30 -> 13 | J30: 3 | K30: =IF(J30=1,"Cambiar",IF(J30=2,"Presupuestar",IF(H30=0,"Activo",IF(G30+H30<YEAR(TODAY()),"Cambiar o Inspección externa",IF(G30+H30-1<YEAR(TODAY()),"Presupuestar","Activo"))))) -> Activo | L30: N/A | Q30: 365 | R30: Empresa externa | S30: 46198 | T30: =+S30+Q30 -> 46563 | U30: =T30-TODAY() -> 302 | V30: =IF(U30<0, "VENCIDO", "AL DÍA") -> AL DÍA | W30: Operativo | X30: GENERAL | Y30: 2
A31: CICLO INICIAL | B31: 1° Piso | C31: K1A | D31: Infraestructura | F31: Enchufes | G31: 2013 | H31: 0 | I31: =YEAR(TODAY())-G31 -> 13 | J31: 3 | K31: =IF(J31=1,"Cambiar",IF(J31=2,"Presupuestar",IF(H31=0,"Activo",IF(G31+H31<YEAR(TODAY()),"Cambiar o Inspección externa",IF(G31+H31-1<YEAR(TODAY()),"Presupuestar","Activo"))))) -> Activo | L31: N/A | O31: 10 Amperes | Q31: 365 | R31: Empresa externa | S31: 46198 | T31: =+S31+Q31 -> 46563 | U31: =T31-TODAY() -> 302 | V31: =IF(U31<0, "VENCIDO", "AL DÍA") -> AL DÍA | W31: Operativo | X31: GENERAL | Y31: 2
A32: CICLO INICIAL | B32: 1° Piso | C32: K1A | D32: Equipo | F32: TV | G32: 2019 | H32: 15 | I32: =YEAR(TODAY())-G32 -> 7 | J32: 3 | K32: =IF(J32=1,"Cambiar",IF(J32=2,"Presupuestar",IF(H32=0,"Activo",IF(G32+H32<YEAR(TODAY()),"Cambiar o Inspección externa",IF(G32+H32-1<YEAR(TODAY()),"Presupuestar","Activo"))))) -> Activo | O32: 65" | P32: N/A | Q32: 365 | R32: Empresa externa | S32: 46198 | T32: =+S32+Q32 -> 46563 | U32: =T32-TODAY() -> 302 | V32: =IF(U32<0, "VENCIDO", "AL DÍA") -> AL DÍA | W32: Operativo | X32: OPERACIÓN | Y32: 2 | Z32: Profesores la utilizan como herramienta pedagógica (para proyectar diapositivas, videos educativos o conectar computadoras).
A33: CICLO INICIAL | B33: 1° Piso | C33: K1A | D33: Equipo | F33: Pizarra | G33: 2013 | H33: 0 | I33: =YEAR(TODAY())-G33 -> 13 | J33: 3 | K33: =IF(J33=1,"Cambiar",IF(J33=2,"Presupuestar",IF(H33=0,"Activo",IF(G33+H33<YEAR(TODAY()),"Cambiar o Inspección externa",IF(G33+H33-1<YEAR(TODAY()),"Presupuestar","Activo"))))) -> Activo | Q33: 365 | R33: Empresa externa | S33: 46198 | T33: =+S33+Q33 -> 46563 | U33: =T33-TODAY() -> 302 | V33: =IF(U33<0, "VENCIDO", "AL DÍA") -> AL DÍA | W33: Operativo | X33: OPERACIÓN | Y33: 2
A34: CICLO INICIAL | B34: 1° Piso | C34: K1A | D34: Infraestructura | F34: Puertas | G34: 2013 | H34: 0 | I34: =YEAR(TODAY())-G34 -> 13 | J34: 3 | K34: =IF(J34=1,"Cambiar",IF(J34=2,"Presupuestar",IF(H34=0,"Activo",IF(G34+H34<YEAR(TODAY()),"Cambiar o Inspección externa",IF(G34+H34-1<YEAR(TODAY()),"Presupuestar","Activo"))))) -> Activo | L34: N/A | O34: Madera Vidrio | Q34: 365 | R34: Empresa externa | S34: 46198 | T34: =+S34+Q34 -> 46563 | U34: =T34-TODAY() -> 302 | V34: =IF(U34<0, "VENCIDO", "AL DÍA") -> AL DÍA | W34: Operativo | X34: GENERAL | Y34: 2
A35: CICLO INICIAL | B35: 1° Piso | C35: K1B | D35: Infraestructura | F35: Ventanas | G35: 2013 | H35: 0 | I35: =YEAR(TODAY())-G35 -> 13 | J35: 3 | K35: =IF(J35=1,"Cambiar",IF(J35=2,"Presupuestar",IF(H35=0,"Activo",IF(G35+H35<YEAR(TODAY()),"Cambiar o Inspección externa",IF(G35+H35-1<YEAR(TODAY()),"Presupuestar","Activo"))))) -> Activo | L35: N/A | M35: N/A | N35: N/A | P35: Anual | Q35: 365 | R35: Empresa externa | S35: 46198 | T35: =+S35+Q35 -> 46563 | U35: =T35-TODAY() -> 302 | V35: =IF(U35<0, "VENCIDO", "AL DÍA") -> AL DÍA | W35: Operativo | X35: SEGURIDAD | Y35: 2 | Z35: Distribución primaria de energía; vital para la integridad de la red.
A36: CICLO INICIAL | B36: 1° Piso | C36: K1B | D36: Infraestructura | E36: Climatización | F36: Radiadores | G36: 2013 | H36: 20 | I36: =YEAR(TODAY())-G36 -> 13 | J36: 3 | K36: =IF(J36=1,"Cambiar",IF(J36=2,"Presupuestar",IF(H36=0,"Activo",IF(G36+H36<YEAR(TODAY()),"Cambiar o Inspección externa",IF(G36+H36-1<YEAR(TODAY()),"Presupuestar","Activo"))))) -> Activo | L36: SIN INFORMACIÓN | P36: Anual | Q36: 365 | R36: Operaciones DSV | S36: 46198 | T36: =+S36+Q36 -> 46563 | U36: =T36-TODAY() -> 302 | V36: =IF(U36<0, "VENCIDO", "AL DÍA") -> AL DÍA | W36: Operativo | X36: GENERAL | Y36: 1 | Z36: Emisores de calor (el sistema principal es Operación).
A37: CICLO INICIAL | B37: 1° Piso | C37: K1B | D37: Infraestructura | F37: Piso | G37: 2013 | H37: 0 | I37: =YEAR(TODAY())-G37 -> 13 | J37: 3 | K37: =IF(J37=1,"Cambiar",IF(J37=2,"Presupuestar",IF(H37=0,"Activo",IF(G37+H37<YEAR(TODAY()),"Cambiar o Inspección externa",IF(G37+H37-1<YEAR(TODAY()),"Presupuestar","Activo"))))) -> Activo | L37: N/A | Q37: 365 | R37: Empresa externa | S37: 46198 | T37: =+S37+Q37 -> 46563 | U37: =T37-TODAY() -> 302 | V37: =IF(U37<0, "VENCIDO", "AL DÍA") -> AL DÍA | W37: Operativo | X37: GENERAL | Y37: 2
A38: CICLO INICIAL | B38: 1° Piso | C38: K1B | D38: Infraestructura | F38: Enchufes | G38: 2013 | H38: 0 | I38: =YEAR(TODAY())-G38 -> 13 | J38: 3 | K38: =IF(J38=1,"Cambiar",IF(J38=2,"Presupuestar",IF(H38=0,"Activo",IF(G38+H38<YEAR(TODAY()),"Cambiar o Inspección externa",IF(G38+H38-1<YEAR(TODAY()),"Presupuestar","Activo"))))) -> Activo | L38: N/A | O38: 10 Amperes | Q38: 365 | R38: Empresa externa | S38: 46198 | T38: =+S38+Q38 -> 46563 | U38: =T38-TODAY() -> 302 | V38: =IF(U38<0, "VENCIDO", "AL DÍA") -> AL DÍA | W38: Operativo | X38: GENERAL | Y38: 2
A39: CICLO INICIAL | B39: 1° Piso | C39: K1B | D39: Equipo | F39: TV | G39: 2019 | H39: 15 | I39: =YEAR(TODAY())-G39 -> 7 | J39: 3 | K39: =IF(J39=1,"Cambiar",IF(J39=2,"Presupuestar",IF(H39=0,"Activo",IF(G39+H39<YEAR(TODAY()),"Cambiar o Inspección externa",IF(G39+H39-1<YEAR(TODAY()),"Presupuestar","Activo"))))) -> Activo | O39: 65" | P39: N/A | Q39: 365 | R39: Empresa externa | S39: 46198 | T39: =+S39+Q39 -> 46563 | U39: =T39-TODAY() -> 302 | V39: =IF(U39<0, "VENCIDO", "AL DÍA") -> AL DÍA | W39: Operativo | X39: OPERACIÓN | Y39: 2 | Z39: Profesores la utilizan como herramienta pedagógica (para proyectar diapositivas, videos educativos o conectar computadoras).
A40: CICLO INICIAL | B40: 1° Piso | C40: K1B | D40: Equipo | F40: Pizarra | G40: 2013 | H40: 0 | I40: =YEAR(TODAY())-G40 -> 13 | J40: 3 | K40: =IF(J40=1,"Cambiar",IF(J40=2,"Presupuestar",IF(H40=0,"Activo",IF(G40+H40<YEAR(TODAY()),"Cambiar o Inspección externa",IF(G40+H40-1<YEAR(TODAY()),"Presupuestar","Activo"))))) -> Activo | Q40: 365 | R40: Empresa externa | S40: 46198 | T40: =+S40+Q40 -> 46563 | U40: =T40-TODAY() -> 302 | V40: =IF(U40<0, "VENCIDO", "AL DÍA") -> AL DÍA | W40: Operativo | X40: OPERACIÓN | Y40: 2
...

Sheet Gantt 2026-2027
A1: =AND($K3>=M$2, $K3<=EOMONTH(M$2,0)) -> FALSE
A2: Edificio | B2: Área / Nivel | C2: Espacio | D2: Tipo de Equipo | E2: Cambio | F2: Estado Mantención | G2: Clasificación | H2: Prioridad | I2: Fecha de Último Mantenimiento | J2: Fecha de Próximo Mantenimiento | K2: Fecha Gantt | L2: Presupuesto 2026 | M2: 46143 | N2: =EDATE(M2,1) -> 46174 | O2: =EDATE(N2,1) -> 46204 | P2: =EDATE(O2,1) -> 46235 | Q2: =EDATE(P2,1) -> 46266 | R2: =EDATE(Q2,1) -> 46296 | S2: =EDATE(R2,1) -> 46327 | T2: =EDATE(S2,1) -> 46357 | U2: =EDATE(T2,1) -> 46388 | ... AW2: =EDATE(AV2,1) -> 47239
A3: =+'Maestro infraestructura'!A2 -> CASINO | B3: =+'Maestro infraestructura'!B2 -> 1° Piso | C3: =+'Maestro infraestructura'!C2 -> Pasillo trasero | D3: =+'Maestro infraestructura'!F2 -> Calefont | E3: =+'Maestro infraestructura'!K2 -> Activo | F3: =+'Maestro infraestructura'!V2 -> AL DÍA | G3: =+'Maestro infraestructura'!X2 -> OPERACIÓN | H3: =+'Maestro infraestructura'!Y2 -> 2 | J3: =+'Maestro infraestructura'!T2 -> 46511 | K3: =IF(E3="Cambiar o Inspección externa",1/1/2027,IF(E3="cambiar",1/1/2027,J3)) -> 46511
A4: =+'Maestro infraestructura'!A3 -> CASINO | B4: =+'Maestro infraestructura'!B3 -> 1° Piso | C4: =+'Maestro infraestructura'!C3 -> Acceso a Casino | D4: =+'Maestro infraestructura'!F3 -> Terraza metálica y madera | E4: =+'Maestro infraestructura'!K3 -> Activo | F4: =+'Maestro infraestructura'!V3 -> AL DÍA | G4: =+'Maestro infraestructura'!X3 -> GENERAL | H4: =+'Maestro infraestructura'!Y3 -> 1 | I4: =+'Maestro infraestructura'!S3 -> 46073 | J4: =+'Maestro infraestructura'!T3 -> 46438 | K4: =IF(E4="Cambiar o Inspección externa",1/1/2027,IF(E4="cambiar",1/1/2027,J4)) -> 46438
A5: =+'Maestro infraestructura'!A4 -> CASINO | B5: =+'Maestro infraestructura'!B4 -> 1° Piso | C5: =+'Maestro infraestructura'!C4 -> Acceso a Casino | D5: =+'Maestro infraestructura'!F4 -> Tablero eléctrico principal | E5: =+'Maestro infraestructura'!K4 -> Activo | F5: =+'Maestro infraestructura'!V4 -> AL DÍA | G5: =+'Maestro infraestructura'!X4 -> SEGURIDAD | H5: =+'Maestro infraestructura'!Y4 -> 1 | I5: =+'Maestro infraestructura'!S4 -> 46037 | J5: =+'Maestro infraestructura'!T4 -> 46402 | K5: =IF(E5="Cambiar o Inspección externa",1/1/2027,IF(E5="cambiar",1/1/2027,J5)) -> 46402
A6: =+'Maestro infraestructura'!A5 -> CASINO | B6: =+'Maestro infraestructura'!B5 -> 1° Piso | C6: =+'Maestro infraestructura'!C5 -> Cafetería | D6: =+'Maestro infraestructura'!F5 -> Tablero eléctrico secundario | E6: =+'Maestro infraestructura'!K5 -> Activo | F6: =+'Maestro infraestructura'!V5 -> AL DÍA | G6: =+'Maestro infraestructura'!X5 -> OPERACIÓN | H6: =+'Maestro infraestructura'!Y5 -> 2 | J6: =+'Maestro infraestructura'!T5 -> 46402 | K6: =IF(E6="Cambiar o Inspección externa",1/1/2027,IF(E6="cambiar",1/1/2027,J6)) -> 46402
A7: =+'Maestro infraestructura'!A6 -> CASINO | B7: =+'Maestro infraestructura'!B6 -> 1° Piso | C7: =+'Maestro infraestructura'!C6 -> 1° Piso | D7: =+'Maestro infraestructura'!F6 -> Pintura de paredes interior | E7: =+'Maestro infraestructura'!K6 -> Activo | F7: =+'Maestro infraestructura'!V6 -> AL DÍA | G7: =+'Maestro infraestructura'!X6 -> GENERAL | H7: =+'Maestro infraestructura'!Y6 -> 3 | J7: =+'Maestro infraestructura'!T6 -> 46570 | K7: =IF(E7="Cambiar o Inspección externa",1/1/2027,IF(E7="cambiar",1/1/2027,J7)) -> 46570
A8: =+'Maestro infraestructura'!A7 -> CASINO | B8: =+'Maestro infraestructura'!B7 -> 1° Piso | C8: =+'Maestro infraestructura'!C7 -> 1° Piso | D8: =+'Maestro infraestructura'!F7 -> Pintura fachadas | E8: =+'Maestro infraestructura'!K7 -> Activo | F8: =+'Maestro infraestructura'!V7 -> AL DÍA | G8: =+'Maestro infraestructura'!X7 -> GENERAL | H8: =+'Maestro infraestructura'!Y7 -> 1 | I8: =+'Maestro infraestructura'!S7 -> 45301 | J8: =+'Maestro infraestructura'!T7 -> 47126 | K8: =IF(E8="Cambiar o Inspección externa",1/1/2027,IF(E8="cambiar",1/1/2027,J8)) -> 47126
A9: =+'Maestro infraestructura'!A8 -> CASINO | B9: =+'Maestro infraestructura'!B8 -> 1° Piso | C9: =+'Maestro infraestructura'!C8 -> Edificio | D9: =+'Maestro infraestructura'!F8 -> Techumbre Casino | E9: =+'Maestro infraestructura'!K8 -> Cambiar o Inspección externa | F9: =+'Maestro infraestructura'!V8 -> AL DÍA | G9: =+'Maestro infraestructura'!X8 -> SEGURIDAD | H9: =+'Maestro infraestructura'!Y8 -> 1 | I9: =+'Maestro infraestructura'!S8 -> 45672 | J9: =+'Maestro infraestructura'!T8 -> 46949.5 | K9: =IF(E9="Cambiar o Inspección externa",1/1/2027,IF(E9="cambiar",1/1/2027,J9)) -> 0.00049333991 | L9: No
A10: =+'Maestro infraestructura'!A9 -> CASINO | B10: =+'Maestro infraestructura'!B9 -> 1° Piso | C10: =+'Maestro infraestructura'!C9 -> Cocina | D10: =+'Maestro infraestructura'!F9 -> Horno Industrial doble cámara | E10: =+'Maestro infraestructura'!K9 -> Activo | F10: =+'Maestro infraestructura'!V9 -> AL DÍA | G10: =+'Maestro infraestructura'!X9 -> OPERACIÓN | H10: =+'Maestro infraestructura'!Y9 -> 2 | J10: =+'Maestro infraestructura'!T9 -> 46522 | K10: =IF(E10="Cambiar o Inspección externa",1/1/2027,IF(E10="cambiar",1/1/2027,J10)) -> 46522
A11: =+'Maestro infraestructura'!A10 -> CASINO | B11: =+'Maestro infraestructura'!B10 -> 1° Piso | C11: =+'Maestro infraestructura'!C10 -> Cocina | D11: =+'Maestro infraestructura'!F10 -> Cocina Industrial 1 | E11: =+'Maestro infraestructura'!K10 -> Activo | F11: =+'Maestro infraestructura'!V10 -> AL DÍA | G11: =+'Maestro infraestructura'!X10 -> OPERACIÓN | H11: =+'Maestro infraestructura'!Y10 -> 2 | I11: =+'Maestro infraestructura'!S10 -> 46157 | J11: =+'Maestro infraestructura'!T10 -> 46522 | K11: =IF(E11="Cambiar o Inspección externa",1/1/2027,IF(E11="cambiar",1/1/2027,J11)) -> 46522
A12: =+'Maestro infraestructura'!A11 -> CASINO | B12: =+'Maestro infraestructura'!B11 -> 1° Piso | C12: =+'Maestro infraestructura'!C11 -> Cocina | D12: =+'Maestro infraestructura'!F11 -> Cocina Industrial 2 | E12: =+'Maestro infraestructura'!K11 -> Activo | F12: =+'Maestro infraestructura'!V11 -> AL DÍA | G12: =+'Maestro infraestructura'!X11 -> OPERACIÓN | H12: =+'Maestro infraestructura'!Y11 -> 2 | J12: =+'Maestro infraestructura'!T11 -> 46522 | K12: =IF(E12="Cambiar o Inspección externa",1/1/2027,IF(E12="cambiar",1/1/2027,J12)) -> 46522
A13: =+'Maestro infraestructura'!A12 -> CASINO | B13: =+'Maestro infraestructura'!B12 -> 1° Piso | C13: =+'Maestro infraestructura'!C12 -> Cocina | D13: =+'Maestro infraestructura'!F12 -> Campana de extracción | E13: =+'Maestro infraestructura'!K12 -> Activo | F13: =+'Maestro infraestructura'!V12 -> AL DÍA | G13: =+'Maestro infraestructura'!X12 -> OPERACIÓN | H13: =+'Maestro infraestructura'!Y12 -> 2 | J13: =+'Maestro infraestructura'!T12 -> 46522 | K13: =IF(E13="Cambiar o Inspección externa",1/1/2027,IF(E13="cambiar",1/1/2027,J13)) -> 46522
A14: =+'Maestro infraestructura'!A13 -> CASINO | B14: =+'Maestro infraestructura'!B13 -> Piso zócalo | C14: =+'Maestro infraestructura'!C13 -> Werken 1 | D14: =+'Maestro infraestructura'!F13 -> Tablero eléctrico secundario | E14: =+'Maestro infraestructura'!K13 -> Activo | F14: =+'Maestro infraestructura'!V13 -> AL DÍA | G14: =+'Maestro infraestructura'!X13 -> OPERACIÓN | H14: =+'Maestro infraestructura'!Y13 -> 2 | J14: =+'Maestro infraestructura'!T13 -> 46402 | K14: =IF(E14="Cambiar o Inspección externa",1/1/2027,IF(E14="cambiar",1/1/2027,J14)) -> 46402
A15: =+'Maestro infraestructura'!A14 -> CASINO | B15: =+'Maestro infraestructura'!B14 -> Piso zócalo | C15: =+'Maestro infraestructura'!C14 -> Zócalo | D15: =+'Maestro infraestructura'!F14 -> Camarín Hombre | E15: =+'Maestro infraestructura'!K14 -> Activo | F15: =+'Maestro infraestructura'!V14 -> VENCIDO | G15: =+'Maestro infraestructura'!X14 -> LEGAL | H15: =+'Maestro infraestructura'!Y14 -> 1 | I15: =+'Maestro infraestructura'!S14 -> 46228 | J15: =+'Maestro infraestructura'!T14 -> 46258 | K15: =IF(E15="Cambiar o Inspección externa",1/1/2027,IF(E15="cambiar",1/1/2027,J15)) -> 46258 | L15: Sí
A16: =+'Maestro infraestructura'!A15 -> CASINO | B16: =+'Maestro infraestructura'!B15 -> Piso zócalo | C16: =+'Maestro infraestructura'!C15 -> Zócalo | D16: =+'Maestro infraestructura'!F15 -> Camarín Mujeres | E16: =+'Maestro infraestructura'!K15 -> Activo | F16: =+'Maestro infraestructura'!V15 -> VENCIDO | G16: =+'Maestro infraestructura'!X15 -> LEGAL | H16: =+'Maestro infraestructura'!Y15 -> 1 | I16: =+'Maestro infraestructura'!S15 -> 46228 | J16: =+'Maestro infraestructura'!T15 -> 46258 | K16: =IF(E16="Cambiar o Inspección externa",1/1/2027,IF(E16="cambiar",1/1/2027,J16)) -> 46258 | L16: Sí
A17: =+'Maestro infraestructura'!A16 -> CICLO INICIAL | B17: =+'Maestro infraestructura'!B16 -> 1° Piso | C17: =+'Maestro infraestructura'!C16 -> Sala caldera NB | D17: =+'Maestro infraestructura'!F16 -> Caldera | E17: =+'Maestro infraestructura'!K16 -> Activo | F17: =+'Maestro infraestructura'!V16 -> AL DÍA | G17: =+'Maestro infraestructura'!X16 -> OPERACIÓN | H17: =+'Maestro infraestructura'!Y16 -> 1 | I17: =+'Maestro infraestructura'!S16 -> 46198 | J17: =+'Maestro infraestructura'!T16 -> 46563 | K17: =IF(E17="Cambiar o Inspección externa",1/1/2027,IF(E17="cambiar",1/1/2027,J17)) -> 46563
